Error: [next-auth][error][CLIENT_FETCH_ERROR] "\nhttps://next-auth.js.org/errors#client_fetch_error" "Unexpected token '<', \"<!DOCTYPE \"... is not valid JSON" {}
    at createUnhandledError (webpack-internal:///(app-pages-browser)/./node_modules/.pnpm/next@15.2.4_react-dom@19.1.0_react@19.1.0__react@19.1.0/node_modules/next/dist/client/components/errors/console-error.js:27:71)
    at handleClientError (webpack-internal:///(app-pages-browser)/./node_modules/.pnpm/next@15.2.4_react-dom@19.1.0_react@19.1.0__react@19.1.0/node_modules/next/dist/client/components/errors/use-error-handler.js:45:56)
    at console.error (webpack-internal:///(app-pages-browser)/./node_modules/.pnpm/next@15.2.4_react-dom@19.1.0_react@19.1.0__react@19.1.0/node_modules/next/dist/client/components/globals/intercept-console-error.js:47:56)
    at Object.error (webpack-internal:///(app-pages-browser)/./node_modules/.pnpm/next-auth@4.24.11_@auth+core@0.38.0_nodemailer@6.10.1__next@15.2.4_react-dom@19.1.0_react@19._uxwt52aifslcu4tn4xzstcc7bq/node_modules/next-auth/utils/logger.js:37:13)
    at _callee$ (webpack-internal:///(app-pages-browser)/./node_modules/.pnpm/next-auth@4.24.11_@auth+core@0.38.0_nodemailer@6.10.1__next@15.2.4_react-dom@19.1.0_react@19._uxwt52aifslcu4tn4xzstcc7bq/node_modules/next-auth/utils/logger.js:70:31)
    at tryCatch (webpack-internal:///(app-pages-browser)/./node_modules/.pnpm/@babel+runtime@7.27.0/node_modules/@babel/runtime/helpers/regeneratorRuntime.js:45:16)
    at Generator.eval (webpack-internal:///(app-pages-browser)/./node_modules/.pnpm/@babel+runtime@7.27.0/node_modules/@babel/runtime/helpers/regeneratorRuntime.js:133:17)
    at Generator.eval [as next] (webpack-internal:///(app-pages-browser)/./node_modules/.pnpm/@babel+runtime@7.27.0/node_modules/@babel/runtime/helpers/regeneratorRuntime.js:74:21)
    at asyncGeneratorStep (webpack-internal:///(app-pages-browser)/./node_modules/.pnpm/@babel+runtime@7.27.0/node_modules/@babel/runtime/helpers/asyncToGenerator.js:3:17)
    at _next (webpack-internal:///(app-pages-browser)/./node_modules/.pnpm/@babel+runtime@7.27.0/node_modules/@babel/runtime/helpers/asyncToGenerator.js:17:9)
    at eval (webpack-internal:///(app-pages-browser)/./node_modules/.pnpm/@babel+runtime@7.27.0/node_modules/@babel/runtime/helpers/asyncToGenerator.js:22:7)
    at new Promise (<anonymous>)
    at Object.eval (webpack-internal:///(app-pages-browser)/./node_modules/.pnpm/@babel+runtime@7.27.0/node_modules/@babel/runtime/helpers/asyncToGenerator.js:14:12)
    at Object.eval [as error] (webpack-internal:///(app-pages-browser)/./node_modules/.pnpm/next-auth@4.24.11_@auth+core@0.38.0_nodemailer@6.10.1__next@15.2.4_react-dom@19.1.0_react@19._uxwt52aifslcu4tn4xzstcc7bq/node_modules/next-auth/utils/logger.js:102:23)
    at _callee$ (webpack-internal:///(app-pages-browser)/./node_modules/.pnpm/next-auth@4.24.11_@auth+core@0.38.0_nodemailer@6.10.1__next@15.2.4_react-dom@19.1.0_react@19._uxwt52aifslcu4tn4xzstcc7bq/node_modules/next-auth/client/_utils.js:66:18)
    at tryCatch (webpack-internal:///(app-pages-browser)/./node_modules/.pnpm/@babel+runtime@7.27.0/node_modules/@babel/runtime/helpers/regeneratorRuntime.js:45:16)
    at Generator.eval (webpack-internal:///(app-pages-browser)/./node_modules/.pnpm/@babel+runtime@7.27.0/node_modules/@babel/runtime/helpers/regeneratorRuntime.js:133:17)
    at Generator.eval [as throw] (webpack-internal:///(app-pages-browser)/./node_modules/.pnpm/@babel+runtime@7.27.0/node_modules/@babel/runtime/helpers/regeneratorRuntime.js:74:21)
    at asyncGeneratorStep (webpack-internal:///(app-pages-browser)/./node_modules/.pnpm/@babel+runtime@7.27.0/node_modules/@babel/runtime/helpers/asyncToGenerator.js:3:17)
    at _throw (webpack-internal:///(app-pages-browser)/./node_modules/.pnpm/@babel+runtime@7.27.0/node_modules/@babel/runtime/helpers/asyncToGenerator.js:20:9)